Workbook

Sheet BON DE PREPARATION
A1: SARL ANDROMEDE DISTRIBUTION
A2: CITE CHAABIA LOT 16 SECTION 02 BIR TOUTA, ALGER.
A3: R-C : 16/00-1010272 B15 I-F : 001516101027219 ART : 16360128161 N° TEL : 0555048930
A5: BON DE CHARGEMENT
A7: VENDEUR : | B7: MM16F01 - SELMANE SEDDIK
A8: LIVREUR : | B8: ZOUBIRI AMINE
A9: DATE : | B9: 08 07 2023
A11: Code IDH | B11: PRODUITS | C11: Qté/Crt | D11: P.U. | E11: Qté. Vendu | F11: Montant TTC | G11: REMISE SALES BUZZ | H11: % REMISE | I11: REMISE
A12: 2682282 | B12: Le Chat Premium RL 2.5L | C12: 4 | D12: 995 | E12: =+'6'!E12+'12'!E12+'8'!E12+'7'!E12+'2'!E12+'5'!E12+'4'!E12+'9'!E12+'1'!E12+'10'!E12+'3'!E12+'11'!E12+'13'!E12+'14'!E12+'15'!E12+'16'!E12+'17'!E12+'18'!E12+'19'!E12 -> 0 | F12: =C12*D12*E12 -> 0 | H12: 0.06 | I12: =+H12*F12 -> 0
A13: 3035219 | B13: Le Chat LS BAG 2.5kg PROMO | C13: 4 | D13: 695 | E13: =+'6'!E13+'12'!E13+'8'!E13+'7'!E13+'2'!E13+'5'!E13+'4'!E13+'9'!E13+'1'!E13+'10'!E13+'3'!E13+'11'!E13+'13'!E13+'14'!E13+'15'!E13+'16'!E13+'17'!E13+'18'!E13+'19'!E13 -> 0 | F13: =C13*D13*E13 -> 0 | H13: 0.04 | I13: =+H13*F13 -> 0
A14: 3051094 | B14: Bref Moussant 1,75L | C14: 6 | D14: 226 | E14: =+'1'!E14+'2'!E14+'3'!E14+'4'!E14+'5'!E14+'6'!E14+'7'!E14+'8'!E14+'9'!E14+'10'!E14+'11'!E14+'12'!E14+'13'!E14+'14'!E14+'15'!E14+'16'!E14+'17'!E14+'18'!E14+'19'!E14 -> 0 | F14: =C14*D14*E14 -> 0 | H14: 0.04 | I14: =+H14*F14 -> 0
A15: 2823409 | B15: ISIS HS POWDER SDM 300GR LIMITLESS | C15: 25 | D15: 90 | E15: =+'1'!E15+'2'!E15+'3'!E15+'4'!E15+'5'!E15+'6'!E15+'7'!E15+'8'!E15+'9'!E15+'10'!E15+'11'!E15+'12'!E15+'13'!E15+'14'!E15+'15'!E15+'16'!E15+'17'!E15+'18'!E15+'19'!E15 -> 0 | F15: =C15*D15*E15 -> 0 | H15: 0.06 | I15: =+H15*F15 -> 0
A16: 3072722 | B16: BREF Trigger multi-surface 490ml | C16: 12 | D16: 221 | E16: =+'1'!E16+'2'!E16+'3'!E16+'4'!E16+'5'!E16+'6'!E16+'7'!E16+'8'!E16+'9'!E16+'10'!E16+'11'!E16+'12'!E16+'13'!E16+'14'!E16+'15'!E16+'16'!E16+'17'!E16+'18'!E16+'19'!E16 -> 0 | F16: =C16*D16*E16 -> 0 | I16: =+H16*F16 -> 0
A17: 3022693 | B17: Pril ISIS Cold Power 3L Promo | C17: 4 | D17: 595 | E17: =+'1'!E17+'2'!E17+'3'!E17+'4'!E17+'5'!E17+'6'!E17+'7'!E17+'8'!E17+'9'!E17+'10'!E17+'11'!E17+'12'!E17+'13'!E17+'14'!E17+'15'!E17+'16'!E17+'17'!E17+'18'!E17+'19'!E17 -> 0 | F17: =C17*D17*E17 -> 0 | I17: =+H17*F17 -> 0
A18: 2875891 | B18: ISIS HS 300g LEMON LIMITLESS | C18: 25 | D18: 90 | E18: =+'1'!E18+'2'!E18+'3'!E18+'4'!E18+'5'!E18+'6'!E18+'7'!E18+'8'!E18+'9'!E18+'10'!E18+'11'!E18+'12'!E18+'13'!E18+'14'!E18+'15'!E18+'16'!E18+'17'!E18+'18'!E18+'19'!E18 -> 0 | F18: =C18*D18*E18 -> 0 | H18: 0.06 | I18: =+H18*F18 -> 0
A19: 2875892 | B19: ISIS HS 750g LEMON LIMITLESS | C19: 12 | D19: 213 | E19: =+'1'!E19+'2'!E19+'3'!E19+'4'!E19+'5'!E19+'6'!E19+'7'!E19+'8'!E19+'9'!E19+'10'!E19+'11'!E19+'12'!E19+'13'!E19+'14'!E19+'15'!E19+'16'!E19+'17'!E19+'18'!E19+'19'!E19 -> 0 | F19: =C19*D19*E19 -> 0 | H19: 0.06 | I19: =+H19*F19 -> 0
A20: 2875893 | B20: ISIS HS 1,5Kg LEMON LIMITLESS | C20: 8 | D20: 417 | E20: =+'1'!E20+'2'!E20+'3'!E20+'4'!E20+'5'!E20+'6'!E20+'7'!E20+'8'!E20+'9'!E20+'10'!E20+'11'!E20+'12'!E20+'13'!E20+'14'!E20+'15'!E20+'16'!E20+'17'!E20+'18'!E20+'19'!E20 -> 0 | F20: =C20*D20*E20 -> 0 | H20: 0.06 | I20: =+H20*F20 -> 0
A21: 2910278 | B21: Nettoyant Moussant Javelisé 900ml | C21: 12 | D21: 123.5 | E21: =+'1'!E21+'2'!E21+'3'!E21+'4'!E21+'5'!E21+'6'!E21+'7'!E21+'8'!E21+'9'!E21+'10'!E21+'11'!E21+'12'!E21+'13'!E21+'14'!E21+'15'!E21+'16'!E21+'17'!E21+'18'!E21+'19'!E21 -> 0 | F21: =C21*D21*E21 -> 0 | H21: 0.04 | I21: =+H21*F21 -> 0
A22: 2943549 | B22: Pril ISIS Antibactérien 650ML Lemon | C22: 12 | D22: 168 | E22: =+'1'!E22+'2'!E22+'3'!E22+'4'!E22+'5'!E22+'6'!E22+'7'!E22+'8'!E22+'9'!E22+'10'!E22+'11'!E22+'12'!E22+'13'!E22+'14'!E22+'15'!E22+'16'!E22+'17'!E22+'18'!E22+'19'!E22 -> 0 | F22: =C22*D22*E22 -> 0 | I22: =+H22*F22 -> 0
A23: 2951994 | B23: Le Chat Rose 2,5L ADV23 | C23: 4 | D23: 810 | E23: =+'1'!E23+'2'!E23+'3'!E23+'4'!E23+'5'!E23+'6'!E23+'7'!E23+'8'!E23+'9'!E23+'10'!E23+'11'!E23+'12'!E23+'13'!E23+'14'!E23+'15'!E23+'16'!E23+'17'!E23+'18'!E23+'19'!E23 -> 0 | F23: =C23*D23*E23 -> 0 | H23: 0.06 | I23: =+H23*F23 -> 0
A24: 2952074 | B24: Le Chat Regular 2,5L ADV23 | C24: 4 | D24: 810 | E24: =+'1'!E24+'2'!E24+'3'!E24+'4'!E24+'5'!E24+'6'!E24+'7'!E24+'8'!E24+'9'!E24+'10'!E24+'11'!E24+'12'!E24+'13'!E24+'14'!E24+'15'!E24+'16'!E24+'17'!E24+'18'!E24+'19'!E24 -> 0 | F24: =C24*D24*E24 -> 0 | H24: 0.06 | I24: =+H24*F24 -> 0
A25: 2952081 | B25: Le Chat SDM 2,5L ADV23 | C25: 4 | D25: 810 | E25: =+'1'!E25+'2'!E25+'3'!E25+'4'!E25+'5'!E25+'6'!E25+'7'!E25+'8'!E25+'9'!E25+'10'!E25+'11'!E25+'12'!E25+'13'!E25+'14'!E25+'15'!E25+'16'!E25+'17'!E25+'18'!E25+'19'!E25 -> 0 | F25: =C25*D25*E25 -> 0 | H25: 0.06 | I25: =+H25*F25 -> 0
A26: 2952089 | B26: Le Chat Regular 1L ADV23 | C26: 10 | D26: 377 | E26: =+'1'!E26+'2'!E26+'3'!E26+'4'!E26+'5'!E26+'6'!E26+'7'!E26+'8'!E26+'9'!E26+'10'!E26+'11'!E26+'12'!E26+'13'!E26+'14'!E26+'15'!E26+'16'!E26+'17'!E26+'18'!E26+'19'!E26 -> 0 | F26: =C26*D26*E26 -> 0 | H26: 0.06 | I26: =+H26*F26 -> 0
A27: 2952090 | B27: Le Chat Rose 1L ADV23 | C27: 10 | D27: 377 | E27: =+'1'!E27+'2'!E27+'3'!E27+'4'!E27+'5'!E27+'6'!E27+'7'!E27+'8'!E27+'9'!E27+'10'!E27+'11'!E27+'12'!E27+'13'!E27+'14'!E27+'15'!E27+'16'!E27+'17'!E27+'18'!E27+'19'!E27 -> 0 | F27: =C27*D27*E27 -> 0 | H27: 0.06 | I27: =+H27*F27 -> 0
A28: 3035242 | B28: Le chat HDLD 4L ADV 23 non promo | C28: 3 | D28: 1145 | E28: =+'1'!E28+'2'!E28+'3'!E28+'4'!E28+'5'!E28+'6'!E28+'7'!E28+'8'!E28+'9'!E28+'10'!E28+'11'!E28+'12'!E28+'13'!E28+'14'!E28+'15'!E28+'16'!E28+'17'!E28+'18'!E28+'19'!E28 -> 0 | F28: =C28*D28*E28 -> 0 | H28: 0.06 | I28: =+H28*F28 -> 0
A29: 2958928 | B29: Le Chat 2,5kg bag ADV23 | C29: 4 | D29: 792 | E29: =+'1'!E29+'2'!E29+'3'!E29+'4'!E29+'5'!E29+'6'!E29+'7'!E29+'8'!E29+'9'!E29+'10'!E29+'11'!E29+'12'!E29+'13'!E29+'14'!E29+'15'!E29+'16'!E29+'17'!E29+'18'!E29+'19'!E29 -> 0 | F29: =C29*D29*E29 -> 0 | H29: 0.04 | I29: =+H29*F29 -> 0
A30: 2958931 | B30: Le Chat HS Gel 1L ADV23 | C30: 10 | D30: 331 | E30: =+'1'!E30+'2'!E30+'3'!E30+'4'!E30+'5'!E30+'6'!E30+'7'!E30+'8'!E30+'9'!E30+'10'!E30+'11'!E30+'12'!E30+'13'!E30+'14'!E30+'15'!E30+'16'!E30+'17'!E30+'18'!E30+'19'!E30 -> 0 | F30: =C30*D30*E30 -> 0 | H30: 0.04 | I30: =+H30*F30 -> 0
A31: 2958932 | B31: Le Chat HS 300gr ADV23 | C31: 25 | D31: 100 | E31: =+'1'!E31+'2'!E31+'3'!E31+'4'!E31+'5'!E31+'6'!E31+'7'!E31+'8'!E31+'9'!E31+'10'!E31+'11'!E31+'12'!E31+'13'!E31+'14'!E31+'15'!E31+'16'!E31+'17'!E31+'18'!E31+'19'!E31 -> 0 | F31: =C31*D31*E31 -> 0 | H31: 0.04 | I31: =+H31*F31 -> 0
A32: 2958933 | B32: Le Chat HS 750gr ADV23 | C32: 12 | D32: 233 | E32: =+'1'!E32+'2'!E32+'3'!E32+'4'!E32+'5'!E32+'6'!E32+'7'!E32+'8'!E32+'9'!E32+'10'!E32+'11'!E32+'12'!E32+'13'!E32+'14'!E32+'15'!E32+'16'!E32+'17'!E32+'18'!E32+'19'!E32 -> 0 | F32: =C32*D32*E32 -> 0 | H32: 0.04 | I32: =+H32*F32 -> 0
A33: 2970224 | B33: Pril Isis ultra power 1.25L | C33: 12 | D33: 284 | E33: =+'1'!E33+'2'!E33+'3'!E33+'4'!E33+'5'!E33+'6'!E33+'7'!E33+'8'!E33+'9'!E33+'10'!E33+'11'!E33+'12'!E33+'13'!E33+'14'!E33+'15'!E33+'16'!E33+'17'!E33+'18'!E33+'19'!E33 -> 0 | F33: =C33*D33*E33 -> 0 | I33: =+H33*F33 -> 0
A34: 2970482 | B34: Pril Isis ultra power 650ml | C34: 12 | D34: 168 | E34: =+'1'!E34+'2'!E34+'3'!E34+'4'!E34+'5'!E34+'6'!E34+'7'!E34+'8'!E34+'9'!E34+'10'!E34+'11'!E34+'12'!E34+'13'!E34+'14'!E34+'15'!E34+'16'!E34+'17'!E34+'18'!E34+'19'!E34 -> 0 | F34: =C34*D34*E34 -> 0 | I34: =+H34*F34 -> 0
A35: 2975112 | B35: Pril Isis ultra power 3 L | C35: 4 | D35: 664 | E35: =+'1'!E35+'2'!E35+'3'!E35+'4'!E35+'5'!E35+'6'!E35+'7'!E35+'8'!E35+'9'!E35+'10'!E35+'11'!E35+'12'!E35+'13'!E35+'14'!E35+'15'!E35+'16'!E35+'17'!E35+'18'!E35+'19'!E35 -> 0 | F35: =C35*D35*E35 -> 0 | I35: =+H35*F35 -> 0
A36: 2993253 | B36: Bref Triggers Cuisine 500ml | C36: 10 | D36: 221 | E36: =+'1'!E36+'2'!E36+'3'!E36+'4'!E36+'5'!E36+'6'!E36+'7'!E36+'8'!E36+'9'!E36+'10'!E36+'11'!E36+'12'!E36+'13'!E36+'14'!E36+'15'!E36+'16'!E36+'17'!E36+'18'!E36+'19'!E36 -> 0 | F36: =C36*D36*E36 -> 0 | I36: =+H36*F36 -> 0
A37: 2993256 | B37: ISIS Gold 5en1 300g | C37: 25 | D37: 90 | E37: =+'1'!E37+'2'!E37+'3'!E37+'4'!E37+'5'!E37+'6'!E37+'7'!E37+'8'!E37+'9'!E37+'10'!E37+'11'!E37+'12'!E37+'13'!E37+'14'!E37+'15'!E37+'16'!E37+'17'!E37+'18'!E37+'19'!E37 -> 0 | F37: =C37*D37*E37 -> 0 | H37: 0.06 | I37: =+H37*F37 -> 0
A38: 3002104 | B38: ISIS LS bag 2.5kg Lemon | C38: 4 | D38: 723 | E38: =+'1'!E38+'2'!E38+'3'!E38+'4'!E38+'5'!E38+'6'!E38+'7'!E38+'8'!E38+'9'!E38+'10'!E38+'11'!E38+'12'!E38+'13'!E38+'14'!E38+'15'!E38+'16'!E38+'17'!E38+'18'!E38+'19'!E38 -> 0 | F38: =C38*D38*E38 -> 0 | H38: 0.04 | I38: =+H38*F38 -> 0
A39: 3004676 | B39: ISIS gel machine universel 2.5L | C39: 4 | D39: 510 | E39: =+'1'!E39+'2'!E39+'3'!E39+'4'!E39+'5'!E39+'6'!E39+'7'!E39+'8'!E39+'9'!E39+'10'!E39+'11'!E39+'12'!E39+'13'!E39+'14'!E39+'15'!E39+'16'!E39+'17'!E39+'18'!E39+'19'!E39 -> 0 | F39: =C39*D39*E39 -> 0 | H39: 0.04 | I39: =+H39*F39 -> 0
A40: 3004679 | B40: ISIS gel machine universal 900ml | C40: 10 | D40: 265 | E40: =+'1'!E40+'2'!E40+'3'!E40+'4'!E40+'5'!E40+'6'!E40+'7'!E40+'8'!E40+'9'!E40+'10'!E40+'11'!E40+'12'!E40+'13'!E40+'14'!E40+'15'!E40+'16'!E40+'17'!E40+'18'!E40+'19'!E40 -> 0 | F40: =C40*D40*E40 -> 0 | H40: 0.04 | I40: =+H40*F40 -> 0
A41: 3011702 | B41: Bref javel pure power 900mL-DZ | C41: 12 | D41: 86 | E41: =+'1'!E41+'2'!E41+'3'!E41+'4'!E41+'5'!E41+'6'!E41+'7'!E41+'8'!E41+'9'!E41+'10'!E41+'11'!E41+'12'!E41+'13'!E41+'14'!E41+'15'!E41+'16'!E41+'17'!E41+'18'!E41+'19'!E41 -> 0 | F41: =C41*D41*E41 -> 0 | H41: 0.04 | I41: =+H41*F41 -> 0
A42: 3013691 | B42: Bref javel regular pure power 1,75L | C42: 6 | D42: 154 | E42: =+'1'!E42+'2'!E42+'3'!E42+'4'!E42+'5'!E42+'6'!E42+'7'!E42+'8'!E42+'9'!E42+'10'!E42+'11'!E42+'12'!E42+'13'!E42+'14'!E42+'15'!E42+'16'!E42+'17'!E42+'18'!E42+'19'!E42 -> 0 | F42: =C42*D42*E42 -> 0 | H42: 0.04 | I42: =+H42*F42 -> 0
A43: 3013692 | B43: Pril ISIS antibactérien 1.25L | C43: 12 | D43: 284 | E43: =+'1'!E43+'2'!E43+'3'!E43+'4'!E43+'5'!E43+'6'!E43+'7'!E43+'8'!E43+'9'!E43+'10'!E43+'11'!E43+'12'!E43+'13'!E43+'14'!E43+'15'!E43+'16'!E43+'17'!E43+'18'!E43+'19'!E43 -> 0 | F43: =C43*D43*E43 -> 0 | I43: =+H43*F43 -> 0
...

Sheet 1
A1: SARL ANDROMEDE DISTRIBUTION
A2: CITE CHAABIA LOT 16 SECTION 02 BIR TOUTA, ALGER.
A3: R-C : 16/00-1010272 B15 I-F : 001516101027219 ART : 16360128161 N° TEL : 0555048930
A5: BON DE LIVRAISON
A7: CLIENT :
A8: ADRESSE :
A9: DATE : | B9: =+'BON DE PREPARATION'!B9 -> 08 07 2023 | D9: LIVREUR :
A11: Code IDH | B11: PRODUITS | C11: Qté/Crt | D11: P.U. | E11: Qté. Vendu | F11: Montant TTC | G11: REMISE SALES BUZZ | H11: % REMISE | I11: REMISE
A12: 2682282 | B12: Le Chat Premium RL 2.5L | C12: 4 | D12: 995 | F12: =C12*D12*E12 -> 0 | H12: 0.06 | I12: =+H12*F12 -> 0
A13: 3035219 | B13: Le Chat LS BAG 2.5kg PROMO | C13: 4 | D13: 695 | F13: =C13*D13*E13 -> 0 | H13: 0.04 | I13: =+H13*F13 -> 0
A14: 3051094 | B14: Bref Moussant 1,75L | C14: 6 | D14: 226 | F14: =C14*D14*E14 -> 0 | H14: 0.04 | I14: =+H14*F14 -> 0
A15: 2823409 | B15: ISIS HS POWDER SDM 300GR LIMITLESS | C15: 25 | D15: 90 | F15: =C15*D15*E15 -> 0 | H15: 0.06 | I15: =+H15*F15 -> 0
A16: 3072722 | B16: BREF Trigger multi-surface 490ml | C16: 12 | D16: 221 | F16: =C16*D16*E16 -> 0 | I16: =+H16*F16 -> 0
A17: 3022693 | B17: Pril ISIS Cold Power 3L Promo | C17: 4 | D17: 595 | F17: =C17*D17*E17 -> 0 | I17: =+H17*F17 -> 0
A18: 2875891 | B18: ISIS HS 300g LEMON LIMITLESS | C18: 25 | D18: 90 | F18: =C18*D18*E18 -> 0 | H18: 0.06 | I18: =+H18*F18 -> 0
A19: 2875892 | B19: ISIS HS 750g LEMON LIMITLESS | C19: 12 | D19: 213 | F19: =C19*D19*E19 -> 0 | H19: 0.06 | I19: =+H19*F19 -> 0
A20: 2875893 | B20: ISIS HS 1,5Kg LEMON LIMITLESS | C20: 8 | D20: 417 | F20: =C20*D20*E20 -> 0 | H20: 0.06 | I20: =+H20*F20 -> 0
A21: 2910278 | B21: Nettoyant Moussant Javelisé 900ml | C21: 12 | D21: 123.5 | F21: =C21*D21*E21 -> 0 | H21: 0.04 | I21: =+H21*F21 -> 0
A22: 2943549 | B22: Pril ISIS Antibactérien 650ML Lemon | C22: 12 | D22: 168 | F22: =C22*D22*E22 -> 0 | I22: =+H22*F22 -> 0
A23: 2951994 | B23: Le Chat Rose 2,5L ADV23 | C23: 4 | D23: 810 | F23: =C23*D23*E23 -> 0 | H23: 0.06 | I23: =+H23*F23 -> 0
A24: 2952074 | B24: Le Chat Regular 2,5L ADV23 | C24: 4 | D24: 810 | F24: =C24*D24*E24 -> 0 | H24: 0.06 | I24: =+H24*F24 -> 0
A25: 2952081 | B25: Le Chat SDM 2,5L ADV23 | C25: 4 | D25: 810 | F25: =C25*D25*E25 -> 0 | H25: 0.06 | I25: =+H25*F25 -> 0
A26: 2952089 | B26: Le Chat Regular 1L ADV23 | C26: 10 | D26: 377 | F26: =C26*D26*E26 -> 0 | H26: 0.06 | I26: =+H26*F26 -> 0
A27: 2952090 | B27: Le Chat Rose 1L ADV23 | C27: 10 | D27: 377 | F27: =C27*D27*E27 -> 0 | H27: 0.06 | I27: =+H27*F27 -> 0
A28: 3035242 | B28: Le chat HDLD 4L ADV 23 non promo | C28: 3 | D28: 1145 | F28: =C28*D28*E28 -> 0 | H28: 0.06 | I28: =+H28*F28 -> 0
A29: 2958928 | B29: Le Chat 2,5kg bag ADV23 | C29: 4 | D29: 792 | F29: =C29*D29*E29 -> 0 | H29: 0.04 | I29: =+H29*F29 -> 0
A30: 2958931 | B30: Le Chat HS Gel 1L ADV23 | C30: 10 | D30: 331 | F30: =C30*D30*E30 -> 0 | H30: 0.04 | I30: =+H30*F30 -> 0
A31: 2958932 | B31: Le Chat HS 300gr ADV23 | C31: 25 | D31: 100 | F31: =C31*D31*E31 -> 0 | H31: 0.04 | I31: =+H31*F31 -> 0
A32: 2958933 | B32: Le Chat HS 750gr ADV23 | C32: 12 | D32: 233 | F32: =C32*D32*E32 -> 0 | H32: 0.04 | I32: =+H32*F32 -> 0
A33: 2970224 | B33: Pril Isis ultra power 1.25L | C33: 12 | D33: 284 | F33: =C33*D33*E33 -> 0 | I33: =+H33*F33 -> 0
A34: 2970482 | B34: Pril Isis ultra power 650ml | C34: 12 | D34: 168 | F34: =C34*D34*E34 -> 0 | I34: =+H34*F34 -> 0
A35: 2975112 | B35: Pril Isis ultra power 3 L | C35: 4 | D35: 664 | F35: =C35*D35*E35 -> 0 | I35: =+H35*F35 -> 0
A36: 2993253 | B36: Bref Triggers Cuisine 500ml | C36: 10 | D36: 221 | F36: =C36*D36*E36 -> 0 | I36: =+H36*F36 -> 0
A37: 2993256 | B37: ISIS Gold 5en1 300g | C37: 25 | D37: 90 | F37: =C37*D37*E37 -> 0 | H37: 0.06 | I37: =+H37*F37 -> 0
A38: 3002104 | B38: ISIS LS bag 2.5kg Lemon | C38: 4 | D38: 723 | F38: =C38*D38*E38 -> 0 | H38: 0.04 | I38: =+H38*F38 -> 0
A39: 3004676 | B39: ISIS gel machine universel 2.5L | C39: 4 | D39: 510 | F39: =C39*D39*E39 -> 0 | H39: 0.04 | I39: =+H39*F39 -> 0
A40: 3004679 | B40: ISIS gel machine universal 900ml | C40: 10 | D40: 265 | F40: =C40*D40*E40 -> 0 | H40: 0.04 | I40: =+H40*F40 -> 0
A41: 3011702 | B41: Bref javel pure power 900mL-DZ | C41: 12 | D41: 86 | F41: =C41*D41*E41 -> 0 | H41: 0.04 | I41: =+H41*F41 -> 0
A42: 3013691 | B42: Bref javel regular pure power 1,75L | C42: 6 | D42: 154 | F42: =C42*D42*E42 -> 0 | H42: 0.04 | I42: =+H42*F42 -> 0
A43: 3013692 | B43: Pril ISIS antibactérien 1.25L | C43: 12 | D43: 284 | F43: =C43*D43*E43 -> 0 | I43: =+H43*F43 -> 0
...

Sheet 2
A1: SARL ANDROMEDE DISTRIBUTION
A2: CITE CHAABIA LOT 16 SECTION 02 BIR TOUTA, ALGER.
A3: R-C : 16/00-1010272 B15 I-F : 001516101027219 ART : 16360128161 N° TEL : 0555048930
A5: BON DE LIVRAISON
A7: CLIENT :
A8: ADRESSE :
A9: DATE : | B9: =+'BON DE PREPARATION'!B9 -> 08 07 2023 | D9: LIVREUR :
A11: Code IDH | B11: PRODUITS | C11: Qté/Crt | D11: P.U. | E11: Qté. Vendu | F11: Montant TTC | G11: REMISE SALES BUZZ | H11: % REMISE | I11: REMISE
A12: 2682282 | B12: Le Chat Premium RL 2.5L | C12: 4 | D12: 995 | F12: =C12*D12*E12 -> 0 | H12: 0.06 | I12: =+H12*F12 -> 0
A13: 3035219 | B13: Le Chat LS BAG 2.5kg PROMO | C13: 4 | D13: 695 | F13: =C13*D13*E13 -> 0 | H13: 0.04 | I13: =+H13*F13 -> 0
A14: 3051094 | B14: Bref Moussant 1,75L | C14: 6 | D14: 226 | F14: =C14*D14*E14 -> 0 | H14: 0.04 | I14: =+H14*F14 -> 0
A15: 2823409 | B15: ISIS HS POWDER SDM 300GR LIMITLESS | C15: 25 | D15: 90 | F15: =C15*D15*E15 -> 0 | H15: 0.06 | I15: =+H15*F15 -> 0
A16: 3072722 | B16: BREF Trigger multi-surface 490ml | C16: 12 | D16: 221 | F16: =C16*D16*E16 -> 0 | I16: =+H16*F16 -> 0
A17: 3022693 | B17: Pril ISIS Cold Power 3L Promo | C17: 4 | D17: 595 | F17: =C17*D17*E17 -> 0 | I17: =+H17*F17 -> 0
A18: 2875891 | B18: ISIS HS 300g LEMON LIMITLESS | C18: 25 | D18: 90 | F18: =C18*D18*E18 -> 0 | H18: 0.06 | I18: =+H18*F18 -> 0
A19: 2875892 | B19: ISIS HS 750g LEMON LIMITLESS | C19: 12 | D19: 213 | F19: =C19*D19*E19 -> 0 | H19: 0.06 | I19: =+H19*F19 -> 0
A20: 2875893 | B20: ISIS HS 1,5Kg LEMON LIMITLESS | C20: 8 | D20: 417 | F20: =C20*D20*E20 -> 0 | H20: 0.06 | I20: =+H20*F20 -> 0
A21: 2910278 | B21: Nettoyant Moussant Javelisé 900ml | C21: 12 | D21: 123.5 | F21: =C21*D21*E21 -> 0 | H21: 0.04 | I21: =+H21*F21 -> 0
A22: 2943549 | B22: Pril ISIS Antibactérien 650ML Lemon | C22: 12 | D22: 168 | F22: =C22*D22*E22 -> 0 | I22: =+H22*F22 -> 0
A23: 2951994 | B23: Le Chat Rose 2,5L ADV23 | C23: 4 | D23: 810 | F23: =C23*D23*E23 -> 0 | H23: 0.06 | I23: =+H23*F23 -> 0
A24: 2952074 | B24: Le Chat Regular 2,5L ADV23 | C24: 4 | D24: 810 | F24: =C24*D24*E24 -> 0 | H24: 0.06 | I24: =+H24*F24 -> 0
A25: 2952081 | B25: Le Chat SDM 2,5L ADV23 | C25: 4 | D25: 810 | F25: =C25*D25*E25 -> 0 | H25: 0.06 | I25: =+H25*F25 -> 0
A26: 2952089 | B26: Le Chat Regular 1L ADV23 | C26: 10 | D26: 377 | F26: =C26*D26*E26 -> 0 | H26: 0.06 | I26: =+H26*F26 -> 0
A27: 2952090 | B27: Le Chat Rose 1L ADV23 | C27: 10 | D27: 377 | F27: =C27*D27*E27 -> 0 | H27: 0.06 | I27: =+H27*F27 -> 0
A28: 3035242 | B28: Le chat HDLD 4L ADV 23 non promo | C28: 3 | D28: 1145 | F28: =C28*D28*E28 -> 0 | H28: 0.06 | I28: =+H28*F28 -> 0
A29: 2958928 | B29: Le Chat 2,5kg bag ADV23 | C29: 4 | D29: 792 | F29: =C29*D29*E29 -> 0 | H29: 0.04 | I29: =+H29*F29 -> 0
A30: 2958931 | B30: Le Chat HS Gel 1L ADV23 | C30: 10 | D30: 331 | F30: =C30*D30*E30 -> 0 | H30: 0.04 | I30: =+H30*F30 -> 0
A31: 2958932 | B31: Le Chat HS 300gr ADV23 | C31: 25 | D31: 100 | F31: =C31*D31*E31 -> 0 | H31: 0.04 | I31: =+H31*F31 -> 0
A32: 2958933 | B32: Le Chat HS 750gr ADV23 | C32: 12 | D32: 233 | F32: =C32*D32*E32 -> 0 | H32: 0.04 | I32: =+H32*F32 -> 0
A33: 2970224 | B33: Pril Isis ultra power 1.25L | C33: 12 | D33: 284 | F33: =C33*D33*E33 -> 0 | I33: =+H33*F33 -> 0
A34: 2970482 | B34: Pril Isis ultra power 650ml | C34: 12 | D34: 168 | F34: =C34*D34*E34 -> 0 | I34: =+H34*F34 -> 0
A35: 2975112 | B35: Pril Isis ultra power 3 L | C35: 4 | D35: 664 | F35: =C35*D35*E35 -> 0 | I35: =+H35*F35 -> 0
A36: 2993253 | B36: Bref Triggers Cuisine 500ml | C36: 10 | D36: 221 | F36: =C36*D36*E36 -> 0 | I36: =+H36*F36 -> 0
A37: 2993256 | B37: ISIS Gold 5en1 300g | C37: 25 | D37: 90 | F37: =C37*D37*E37 -> 0 | H37: 0.06 | I37: =+H37*F37 -> 0
A38: 3002104 | B38: ISIS LS bag 2.5kg Lemon | C38: 4 | D38: 723 | F38: =C38*D38*E38 -> 0 | H38: 0.04 | I38: =+H38*F38 -> 0
A39: 3004676 | B39: ISIS gel machine universel 2.5L | C39: 4 | D39: 510 | F39: =C39*D39*E39 -> 0 | H39: 0.04 | I39: =+H39*F39 -> 0
A40: 3004679 | B40: ISIS gel machine universal 900ml | C40: 10 | D40: 265 | F40: =C40*D40*E40 -> 0 | H40: 0.04 | I40: =+H40*F40 -> 0
A41: 3011702 | B41: Bref javel pure power 900mL-DZ | C41: 12 | D41: 86 | F41: =C41*D41*E41 -> 0 | H41: 0.04 | I41: =+H41*F41 -> 0
A42: 3013691 | B42: Bref javel regular pure power 1,75L | C42: 6 | D42: 154 | F42: =C42*D42*E42 -> 0 | H42: 0.04 | I42: =+H42*F42 -> 0
A43: 3013692 | B43: Pril ISIS antibactérien 1.25L | C43: 12 | D43: 284 | F43: =C43*D43*E43 -> 0 | I43: =+H43*F43 -> 0
...

Sheet 3
A1: SARL ANDROMEDE DISTRIBUTION
A2: CITE CHAABIA LOT 16 SECTION 02 BIR TOUTA, ALGER.
A3: R-C : 16/00-1010272 B15 I-F : 001516101027219 ART : 16360128161 N° TEL : 0555048930
A5: BON DE LIVRAISON
A7: CLIENT :
A8: ADRESSE :
A9: DATE : | B9: =+'BON DE PREPARATION'!B9 -> 08 07 2023 | D9: LIVREUR :
A11: Code IDH | B11: PRODUITS | C11: Qté/Crt | D11: P.U. | E11: Qté. Vendu | F11: Montant TTC | G11: REMISE SALES BUZZ | H11: % REMISE | I11: REMISE
A12: 2682282 | B12: Le Chat Premium RL 2.5L | C12: 4 | D12: 995 | F12: =C12*D12*E12 -> 0 | H12: 0.06 | I12: =+H12*F12 -> 0
A13: 3035219 | B13: Le Chat LS BAG 2.5kg PROMO | C13: 4 | D13: 695 | F13: =C13*D13*E13 -> 0 | H13: 0.04 | I13: =+H13*F13 -> 0
A14: 3051094 | B14: Bref Moussant 1,75L | C14: 6 | D14: 226 | F14: =C14*D14*E14 -> 0 | H14: 0.04 | I14: =+H14*F14 -> 0
A15: 2823409 | B15: ISIS HS POWDER SDM 300GR LIMITLESS | C15: 25 | D15: 90 | F15: =C15*D15*E15 -> 0 | H15: 0.06 | I15: =+H15*F15 -> 0
A16: 3072722 | B16: BREF Trigger multi-surface 490ml | C16: 12 | D16: 221 | F16: =C16*D16*E16 -> 0 | I16: =+H16*F16 -> 0
A17: 3022693 | B17: Pril ISIS Cold Power 3L Promo | C17: 4 | D17: 595 | F17: =C17*D17*E17 -> 0 | I17: =+H17*F17 -> 0
A18: 2875891 | B18: ISIS HS 300g LEMON LIMITLESS | C18: 25 | D18: 90 | F18: =C18*D18*E18 -> 0 | H18: 0.06 | I18: =+H18*F18 -> 0
A19: 2875892 | B19: ISIS HS 750g LEMON LIMITLESS | C19: 12 | D19: 213 | F19: =C19*D19*E19 -> 0 | H19: 0.06 | I19: =+H19*F19 -> 0
A20: 2875893 | B20: ISIS HS 1,5Kg LEMON LIMITLESS | C20: 8 | D20: 417 | F20: =C20*D20*E20 -> 0 | H20: 0.06 | I20: =+H20*F20 -> 0
A21: 2910278 | B21: Nettoyant Moussant Javelisé 900ml | C21: 12 | D21: 123.5 | F21: =C21*D21*E21 -> 0 | H21: 0.04 | I21: =+H21*F21 -> 0
A22: 2943549 | B22: Pril ISIS Antibactérien 650ML Lemon | C22: 12 | D22: 168 | F22: =C22*D22*E22 -> 0 | I22: =+H22*F22 -> 0
A23: 2951994 | B23: Le Chat Rose 2,5L ADV23 | C23: 4 | D23: 810 | F23: =C23*D23*E23 -> 0 | H23: 0.06 | I23: =+H23*F23 -> 0
A24: 2952074 | B24: Le Chat Regular 2,5L ADV23 | C24: 4 | D24: 810 | F24: =C24*D24*E24 -> 0 | H24: 0.06 | I24: =+H24*F24 -> 0
A25: 2952081 | B25: Le Chat SDM 2,5L ADV23 | C25: 4 | D25: 810 | F25: =C25*D25*E25 -> 0 | H25: 0.06 | I25: =+H25*F25 -> 0
A26: 2952089 | B26: Le Chat Regular 1L ADV23 | C26: 10 | D26: 377 | F26: =C26*D26*E26 -> 0 | H26: 0.06 | I26: =+H26*F26 -> 0
A27: 2952090 | B27: Le Chat Rose 1L ADV23 | C27: 10 | D27: 377 | F27: =C27*D27*E27 -> 0 | H27: 0.06 | I27: =+H27*F27 -> 0
A28: 3035242 | B28: Le chat HDLD 4L ADV 23 non promo | C28: 3 | D28: 1145 | F28: =C28*D28*E28 -> 0 | H28: 0.06 | I28: =+H28*F28 -> 0
A29: 2958928 | B29: Le Chat 2,5kg bag ADV23 | C29: 4 | D29: 792 | F29: =C29*D29*E29 -> 0 | H29: 0.04 | I29: =+H29*F29 -> 0
A30: 2958931 | B30: Le Chat HS Gel 1L ADV23 | C30: 10 | D30: 331 | F30: =C30*D30*E30 -> 0 | H30: 0.04 | I30: =+H30*F30 -> 0
A31: 2958932 | B31: Le Chat HS 300gr ADV23 | C31: 25 | D31: 100 | F31: =C31*D31*E31 -> 0 | H31: 0.04 | I31: =+H31*F31 -> 0
A32: 2958933 | B32: Le Chat HS 750gr ADV23 | C32: 12 | D32: 233 | F32: =C32*D32*E32 -> 0 | H32: 0.04 | I32: =+H32*F32 -> 0
A33: 2970224 | B33: Pril Isis ultra power 1.25L | C33: 12 | D33: 284 | F33: =C33*D33*E33 -> 0 | I33: =+H33*F33 -> 0
A34: 2970482 | B34: Pril Isis ultra power 650ml | C34: 12 | D34: 168 | F34: =C34*D34*E34 -> 0 | I34: =+H34*F34 -> 0
A35: 2975112 | B35: Pril Isis ultra power 3 L | C35: 4 | D35: 664 | F35: =C35*D35*E35 -> 0 | I35: =+H35*F35 -> 0
A36: 2993253 | B36: Bref Triggers Cuisine 500ml | C36: 10 | D36: 221 | F36: =C36*D36*E36 -> 0 | I36: =+H36*F36 -> 0
A37: 2993256 | B37: ISIS Gold 5en1 300g | C37: 25 | D37: 90 | F37: =C37*D37*E37 -> 0 | H37: 0.06 | I37: =+H37*F37 -> 0
A38: 3002104 | B38: ISIS LS bag 2.5kg Lemon | C38: 4 | D38: 723 | F38: =C38*D38*E38 -> 0 | H38: 0.04 | I38: =+H38*F38 -> 0
A39: 3004676 | B39: ISIS gel machine universel 2.5L | C39: 4 | D39: 510 | F39: =C39*D39*E39 -> 0 | H39: 0.04 | I39: =+H39*F39 -> 0
A40: 3004679 | B40: ISIS gel machine universal 900ml | C40: 10 | D40: 265 | F40: =C40*D40*E40 -> 0 | H40: 0.04 | I40: =+H40*F40 -> 0
A41: 3011702 | B41: Bref javel pure power 900mL-DZ | C41: 12 | D41: 86 | F41: =C41*D41*E41 -> 0 | H41: 0.04 | I41: =+H41*F41 -> 0
A42: 3013691 | B42: Bref javel regular pure power 1,75L | C42: 6 | D42: 154 | F42: =C42*D42*E42 -> 0 | H42: 0.04 | I42: =+H42*F42 -> 0
A43: 3013692 | B43: Pril ISIS antibactérien 1.25L | C43: 12 | D43: 284 | F43: =C43*D43*E43 -> 0 | I43: =+H43*F43 -> 0
...

Sheet 4
A1: SARL ANDROMEDE DISTRIBUTION
A2: CITE CHAABIA LOT 16 SECTION 02 BIR TOUTA, ALGER.
A3: R-C : 16/00-1010272 B15 I-F : 001516101027219 ART : 16360128161 N° TEL : 0555048930
A5: BON DE LIVRAISON
A7: CLIENT :
A8: ADRESSE :
A9: DATE : | B9: =+'BON DE PREPARATION'!B9 -> 08 07 2023 | D9: LIVREUR :
A11: Code IDH | B11: PRODUITS | C11: Qté/Crt | D11: P.U. | E11: Qté. Vendu | F11: Montant TTC | G11: REMISE SALES BUZZ | H11: % REMISE | I11: REMISE
A12: 2682282 | B12: Le Chat Premium RL 2.5L | C12: 4 | D12: 995 | F12: =C12*D12*E12 -> 0 | H12: 0.06 | I12: =+H12*F12 -> 0
A13: 3035219 | B13: Le Chat LS BAG 2.5kg PROMO | C13: 4 | D13: 695 | F13: =C13*D13*E13 -> 0 | H13: 0.04 | I13: =+H13*F13 -> 0
A14: 3051094 | B14: Bref Moussant 1,75L | C14: 6 | D14: 226 | F14: =C14*D14*E14 -> 0 | H14: 0.04 | I14: =+H14*F14 -> 0
A15: 2823409 | B15: ISIS HS POWDER SDM 300GR LIMITLESS | C15: 25 | D15: 90 | F15: =C15*D15*E15 -> 0 | H15: 0.06 | I15: =+H15*F15 -> 0
A16: 3072722 | B16: BREF Trigger multi-surface 490ml | C16: 12 | D16: 221 | F16: =C16*D16*E16 -> 0 | I16: =+H16*F16 -> 0
A17: 3022693 | B17: Pril ISIS Cold Power 3L Promo | C17: 4 | D17: 595 | F17: =C17*D17*E17 -> 0 | I17: =+H17*F17 -> 0
A18: 2875891 | B18: ISIS HS 300g LEMON LIMITLESS | C18: 25 | D18: 90 | F18: =C18*D18*E18 -> 0 | H18: 0.06 | I18: =+H18*F18 -> 0
A19: 2875892 | B19: ISIS HS 750g LEMON LIMITLESS | C19: 12 | D19: 213 | F19: =C19*D19*E19 -> 0 | H19: 0.06 | I19: =+H19*F19 -> 0
A20: 2875893 | B20: ISIS HS 1,5Kg LEMON LIMITLESS | C20: 8 | D20: 417 | F20: =C20*D20*E20 -> 0 | H20: 0.06 | I20: =+H20*F20 -> 0
A21: 2910278 | B21: Nettoyant Moussant Javelisé 900ml | C21: 12 | D21: 123.5 | F21: =C21*D21*E21 -> 0 | H21: 0.04 | I21: =+H21*F21 -> 0
A22: 2943549 | B22: Pril ISIS Antibactérien 650ML Lemon | C22: 12 | D22: 168 | F22: =C22*D22*E22 -> 0 | I22: =+H22*F22 -> 0
A23: 2951994 | B23: Le Chat Rose 2,5L ADV23 | C23: 4 | D23: 810 | F23: =C23*D23*E23 -> 0 | H23: 0.06 | I23: =+H23*F23 -> 0
A24: 2952074 | B24: Le Chat Regular 2,5L ADV23 | C24: 4 | D24: 810 | F24: =C24*D24*E24 -> 0 | H24: 0.06 | I24: =+H24*F24 -> 0
A25: 2952081 | B25: Le Chat SDM 2,5L ADV23 | C25: 4 | D25: 810 | F25: =C25*D25*E25 -> 0 | H25: 0.06 | I25: =+H25*F25 -> 0
A26: 2952089 | B26: Le Chat Regular 1L ADV23 | C26: 10 | D26: 377 | F26: =C26*D26*E26 -> 0 | H26: 0.06 | I26: =+H26*F26 -> 0
A27: 2952090 | B27: Le Chat Rose 1L ADV23 | C27: 10 | D27: 377 | F27: =C27*D27*E27 -> 0 | H27: 0.06 | I27: =+H27*F27 -> 0
A28: 3035242 | B28: Le chat HDLD 4L ADV 23 non promo | C28: 3 | D28: 1145 | F28: =C28*D28*E28 -> 0 | H28: 0.06 | I28: =+H28*F28 -> 0
A29: 2958928 | B29: Le Chat 2,5kg bag ADV23 | C29: 4 | D29: 792 | F29: =C29*D29*E29 -> 0 | H29: 0.04 | I29: =+H29*F29 -> 0
A30: 2958931 | B30: Le Chat HS Gel 1L ADV23 | C30: 10 | D30: 331 | F30: =C30*D30*E30 -> 0 | H30: 0.04 | I30: =+H30*F30 -> 0
A31: 2958932 | B31: Le Chat HS 300gr ADV23 | C31: 25 | D31: 100 | F31: =C31*D31*E31 -> 0 | H31: 0.04 | I31: =+H31*F31 -> 0
A32: 2958933 | B32: Le Chat HS 750gr ADV23 | C32: 12 | D32: 233 | F32: =C32*D32*E32 -> 0 | H32: 0.04 | I32: =+H32*F32 -> 0
A33: 2970224 | B33: Pril Isis ultra power 1.25L | C33: 12 | D33: 284 | F33: =C33*D33*E33 -> 0 | I33: =+H33*F33 -> 0
A34: 2970482 | B34: Pril Isis ultra power 650ml | C34: 12 | D34: 168 | F34: =C34*D34*E34 -> 0 | I34: =+H34*F34 -> 0
A35: 2975112 | B35: Pril Isis ultra power 3 L | C35: 4 | D35: 664 | F35: =C35*D35*E35 -> 0 | I35: =+H35*F35 -> 0
A36: 2993253 | B36: Bref Triggers Cuisine 500ml | C36: 10 | D36: 221 | F36: =C36*D36*E36 -> 0 | I36: =+H36*F36 -> 0
A37: 2993256 | B37: ISIS Gold 5en1 300g | C37: 25 | D37: 90 | F37: =C37*D37*E37 -> 0 | H37: 0.06 | I37: =+H37*F37 -> 0
A38: 3002104 | B38: ISIS LS bag 2.5kg Lemon | C38: 4 | D38: 723 | F38: =C38*D38*E38 -> 0 | H38: 0.04 | I38: =+H38*F38 -> 0
A39: 3004676 | B39: ISIS gel machine universel 2.5L | C39: 4 | D39: 510 | F39: =C39*D39*E39 -> 0 | H39: 0.04 | I39: =+H39*F39 -> 0
A40: 3004679 | B40: ISIS gel machine universal 900ml | C40: 10 | D40: 265 | F40: =C40*D40*E40 -> 0 | H40: 0.04 | I40: =+H40*F40 -> 0
A41: 3011702 | B41: Bref javel pure power 900mL-DZ | C41: 12 | D41: 86 | F41: =C41*D41*E41 -> 0 | H41: 0.04 | I41: =+H41*F41 -> 0
A42: 3013691 | B42: Bref javel regular pure power 1,75L | C42: 6 | D42: 154 | F42: =C42*D42*E42 -> 0 | H42: 0.04 | I42: =+H42*F42 -> 0
A43: 3013692 | B43: Pril ISIS antibactérien 1.25L | C43: 12 | D43: 284 | F43: =C43*D43*E43 -> 0 | I43: =+H43*F43 -> 0
...

Sheet 5
A1: SARL ANDROMEDE DISTRIBUTION
A2: CITE CHAABIA LOT 16 SECTION 02 BIR TOUTA, ALGER.
A3: R-C : 16/00-1010272 B15 I-F : 001516101027219 ART : 16360128161 N° TEL : 0555048930
A5: BON DE LIVRAISON
A7: CLIENT :
A8: ADRESSE :
A9: DATE : | B9: =+'BON DE PREPARATION'!B9 -> 08 07 2023 | D9: LIVREUR :
A11: Code IDH | B11: PRODUITS | C11: Qté/Crt | D11: P.U. | E11: Qté. Vendu | F11: Montant TTC | G11: REMISE SALES BUZZ | H11: % REMISE | I11: REMISE
A12: 2682282 | B12: Le Chat Premium RL 2.5L | C12: 4 | D12: 995 | F12: =C12*D12*E12 -> 0 | H12: 0.06 | I12: =+H12*F12 -> 0
A13: 3035219 | B13: Le Chat LS BAG 2.5kg PROMO | C13: 4 | D13: 695 | F13: =C13*D13*E13 -> 0 | H13: 0.04 | I13: =+H13*F13 -> 0
A14: 3051094 | B14: Bref Moussant 1,75L | C14: 6 | D14: 226 | F14: =C14*D14*E14 -> 0 | H14: 0.04 | I14: =+H14*F14 -> 0
A15: 2823409 | B15: ISIS HS POWDER SDM 300GR LIMITLESS | C15: 25 | D15: 90 | F15: =C15*D15*E15 -> 0 | H15: 0.06 | I15: =+H15*F15 -> 0
A16: 3072722 | B16: BREF Trigger multi-surface 490ml | C16: 12 | D16: 221 | F16: =C16*D16*E16 -> 0 | I16: =+H16*F16 -> 0
A17: 3022693 | B17: Pril ISIS Cold Power 3L Promo | C17: 4 | D17: 595 | F17: =C17*D17*E17 -> 0 | I17: =+H17*F17 -> 0
A18: 2875891 | B18: ISIS HS 300g LEMON LIMITLESS | C18: 25 | D18: 90 | F18: =C18*D18*E18 -> 0 | H18: 0.06 | I18: =+H18*F18 -> 0
A19: 2875892 | B19: ISIS HS 750g LEMON LIMITLESS | C19: 12 | D19: 213 | F19: =C19*D19*E19 -> 0 | H19: 0.06 | I19: =+H19*F19 -> 0
A20: 2875893 | B20: ISIS HS 1,5Kg LEMON LIMITLESS | C20: 8 | D20: 417 | F20: =C20*D20*E20 -> 0 | H20: 0.06 | I20: =+H20*F20 -> 0
A21: 2910278 | B21: Nettoyant Moussant Javelisé 900ml | C21: 12 | D21: 123.5 | F21: =C21*D21*E21 -> 0 | H21: 0.04 | I21: =+H21*F21 -> 0
A22: 2943549 | B22: Pril ISIS Antibactérien 650ML Lemon | C22: 12 | D22: 168 | F22: =C22*D22*E22 -> 0 | I22: =+H22*F22 -> 0
A23: 2951994 | B23: Le Chat Rose 2,5L ADV23 | C23: 4 | D23: 810 | F23: =C23*D23*E23 -> 0 | H23: 0.06 | I23: =+H23*F23 -> 0
A24: 2952074 | B24: Le Chat Regular 2,5L ADV23 | C24: 4 | D24: 810 | F24: =C24*D24*E24 -> 0 | H24: 0.06 | I24: =+H24*F24 -> 0
A25: 2952081 | B25: Le Chat SDM 2,5L ADV23 | C25: 4 | D25: 810 | F25: =C25*D25*E25 -> 0 | H25: 0.06 | I25: =+H25*F25 -> 0
A26: 2952089 | B26: Le Chat Regular 1L ADV23 | C26: 10 | D26: 377 | F26: =C26*D26*E26 -> 0 | H26: 0.06 | I26: =+H26*F26 -> 0
A27: 2952090 | B27: Le Chat Rose 1L ADV23 | C27: 10 | D27: 377 | F27: =C27*D27*E27 -> 0 | H27: 0.06 | I27: =+H27*F27 -> 0
A28: 3035242 | B28: Le chat HDLD 4L ADV 23 non promo | C28: 3 | D28: 1145 | F28: =C28*D28*E28 -> 0 | H28: 0.06 | I28: =+H28*F28 -> 0
A29: 2958928 | B29: Le Chat 2,5kg bag ADV23 | C29: 4 | D29: 792 | F29: =C29*D29*E29 -> 0 | H29: 0.04 | I29: =+H29*F29 -> 0
A30: 2958931 | B30: Le Chat HS Gel 1L ADV23 | C30: 10 | D30: 331 | F30: =C30*D30*E30 -> 0 | H30: 0.04 | I30: =+H30*F30 -> 0
A31: 2958932 | B31: Le Chat HS 300gr ADV23 | C31: 25 | D31: 100 | F31: =C31*D31*E31 -> 0 | H31: 0.04 | I31: =+H31*F31 -> 0
A32: 2958933 | B32: Le Chat HS 750gr ADV23 | C32: 12 | D32: 233 | F32: =C32*D32*E32 -> 0 | H32: 0.04 | I32: =+H32*F32 -> 0
A33: 2970224 | B33: Pril Isis ultra power 1.25L | C33: 12 | D33: 284 | F33: =C33*D33*E33 -> 0 | I33: =+H33*F33 -> 0
A34: 2970482 | B34: Pril Isis ultra power 650ml | C34: 12 | D34: 168 | F34: =C34*D34*E34 -> 0 | I34: =+H34*F34 -> 0
A35: 2975112 | B35: Pril Isis ultra power 3 L | C35: 4 | D35: 664 | F35: =C35*D35*E35 -> 0 | I35: =+H35*F35 -> 0
A36: 2993253 | B36: Bref Triggers Cuisine 500ml | C36: 10 | D36: 221 | F36: =C36*D36*E36 -> 0 | I36: =+H36*F36 -> 0
A37: 2993256 | B37: ISIS Gold 5en1 300g | C37: 25 | D37: 90 | F37: =C37*D37*E37 -> 0 | H37: 0.06 | I37: =+H37*F37 -> 0
A38: 3002104 | B38: ISIS LS bag 2.5kg Lemon | C38: 4 | D38: 723 | F38: =C38*D38*E38 -> 0 | H38: 0.04 | I38: =+H38*F38 -> 0
A39: 3004676 | B39: ISIS gel machine universel 2.5L | C39: 4 | D39: 510 | F39: =C39*D39*E39 -> 0 | H39: 0.04 | I39: =+H39*F39 -> 0
A40: 3004679 | B40: ISIS gel machine universal 900ml | C40: 10 | D40: 265 | F40: =C40*D40*E40 -> 0 | H40: 0.04 | I40: =+H40*F40 -> 0
A41: 3011702 | B41: Bref javel pure power 900mL-DZ | C41: 12 | D41: 86 | F41: =C41*D41*E41 -> 0 | H41: 0.04 | I41: =+H41*F41 -> 0
A42: 3013691 | B42: Bref javel regular pure power 1,75L | C42: 6 | D42: 154 | F42: =C42*D42*E42 -> 0 | H42: 0.04 | I42: =+H42*F42 -> 0
A43: 3013692 | B43: Pril ISIS antibactérien 1.25L | C43: 12 | D43: 284 | F43: =C43*D43*E43 -> 0 | I43: =+H43*F43 -> 0
...

Sheet 6
A1: SARL ANDROMEDE DISTRIBUTION
A2: CITE CHAABIA LOT 16 SECTION 02 BIR TOUTA, ALGER.
A3: R-C : 16/00-1010272 B15 I-F : 001516101027219 ART : 16360128161 N° TEL : 0555048930
A5: BON DE LIVRAISON
A7: CLIENT :
A8: ADRESSE :
A9: DATE : | B9: =+'BON DE PREPARATION'!B9 -> 08 07 2023 | D9: LIVREUR :
B10: BACHDJERAH HUSSEIN DEY EL MAGHARIA BOUROUBA
A11: Code IDH | B11: PRODUITS | C11: Qté/Crt | D11: P.U. | E11: Qté. Vendu | F11: Montant TTC | G11: REMISE SALES BUZZ | H11: % REMISE | I11: REMISE
A12: 2682282 | B12: Le Chat Premium RL 2.5L | C12: 4 | D12: 995 | F12: =C12*D12*E12 -> 0 | H12: 0.06 | I12: =+H12*F12 -> 0
A13: 3035219 | B13: Le Chat LS BAG 2.5kg PROMO | C13: 4 | D13: 695 | F13: =C13*D13*E13 -> 0 | H13: 0.04 | I13: =+H13*F13 -> 0
A14: 3051094 | B14: Bref Moussant 1,75L | C14: 6 | D14: 226 | F14: =C14*D14*E14 -> 0 | H14: 0.04 | I14: =+H14*F14 -> 0
A15: 2823409 | B15: ISIS HS POWDER SDM 300GR LIMITLESS | C15: 25 | D15: 90 | F15: =C15*D15*E15 -> 0 | H15: 0.06 | I15: =+H15*F15 -> 0
A16: 3072722 | B16: BREF Trigger multi-surface 490ml | C16: 12 | D16: 221 | F16: =C16*D16*E16 -> 0 | I16: =+H16*F16 -> 0
A17: 3022693 | B17: Pril ISIS Cold Power 3L Promo | C17: 4 | D17: 595 | F17: =C17*D17*E17 -> 0 | I17: =+H17*F17 -> 0
A18: 2875891 | B18: ISIS HS 300g LEMON LIMITLESS | C18: 25 | D18: 90 | F18: =C18*D18*E18 -> 0 | H18: 0.06 | I18: =+H18*F18 -> 0
A19: 2875892 | B19: ISIS HS 750g LEMON LIMITLESS | C19: 12 | D19: 213 | F19: =C19*D19*E19 -> 0 | H19: 0.06 | I19: =+H19*F19 -> 0
A20: 2875893 | B20: ISIS HS 1,5Kg LEMON LIMITLESS | C20: 8 | D20: 417 | F20: =C20*D20*E20 -> 0 | H20: 0.06 | I20: =+H20*F20 -> 0
A21: 2910278 | B21: Nettoyant Moussant Javelisé 900ml | C21: 12 | D21: 123.5 | F21: =C21*D21*E21 -> 0 | H21: 0.04 | I21: =+H21*F21 -> 0
A22: 2943549 | B22: Pril ISIS Antibactérien 650ML Lemon | C22: 12 | D22: 168 | F22: =C22*D22*E22 -> 0 | I22: =+H22*F22 -> 0
A23: 2951994 | B23: Le Chat Rose 2,5L ADV23 | C23: 4 | D23: 810 | F23: =C23*D23*E23 -> 0 | H23: 0.06 | I23: =+H23*F23 -> 0
A24: 2952074 | B24: Le Chat Regular 2,5L ADV23 | C24: 4 | D24: 810 | F24: =C24*D24*E24 -> 0 | H24: 0.06 | I24: =+H24*F24 -> 0
A25: 2952081 | B25: Le Chat SDM 2,5L ADV23 | C25: 4 | D25: 810 | F25: =C25*D25*E25 -> 0 | H25: 0.06 | I25: =+H25*F25 -> 0
A26: 2952089 | B26: Le Chat Regular 1L ADV23 | C26: 10 | D26: 377 | F26: =C26*D26*E26 -> 0 | H26: 0.06 | I26: =+H26*F26 -> 0
A27: 2952090 | B27: Le Chat Rose 1L ADV23 | C27: 10 | D27: 377 | F27: =C27*D27*E27 -> 0 | H27: 0.06 | I27: =+H27*F27 -> 0
A28: 3035242 | B28: Le chat HDLD 4L ADV 23 non promo | C28: 3 | D28: 1145 | F28: =C28*D28*E28 -> 0 | H28: 0.06 | I28: =+H28*F28 -> 0
A29: 2958928 | B29: Le Chat 2,5kg bag ADV23 | C29: 4 | D29: 792 | F29: =C29*D29*E29 -> 0 | H29: 0.04 | I29: =+H29*F29 -> 0
A30: 2958931 | B30: Le Chat HS Gel 1L ADV23 | C30: 10 | D30: 331 | F30: =C30*D30*E30 -> 0 | H30: 0.04 | I30: =+H30*F30 -> 0
A31: 2958932 | B31: Le Chat HS 300gr ADV23 | C31: 25 | D31: 100 | F31: =C31*D31*E31 -> 0 | H31: 0.04 | I31: =+H31*F31 -> 0
A32: 2958933 | B32: Le Chat HS 750gr ADV23 | C32: 12 | D32: 233 | F32: =C32*D32*E32 -> 0 | H32: 0.04 | I32: =+H32*F32 -> 0
A33: 2970224 | B33: Pril Isis ultra power 1.25L | C33: 12 | D33: 284 | F33: =C33*D33*E33 -> 0 | I33: =+H33*F33 -> 0
A34: 2970482 | B34: Pril Isis ultra power 650ml | C34: 12 | D34: 168 | F34: =C34*D34*E34 -> 0 | I34: =+H34*F34 -> 0
A35: 2975112 | B35: Pril Isis ultra power 3 L | C35: 4 | D35: 664 | F35: =C35*D35*E35 -> 0 | I35: =+H35*F35 -> 0
A36: 2993253 | B36: Bref Triggers Cuisine 500ml | C36: 10 | D36: 221 | F36: =C36*D36*E36 -> 0 | I36: =+H36*F36 -> 0
A37: 2993256 | B37: ISIS Gold 5en1 300g | C37: 25 | D37: 90 | F37: =C37*D37*E37 -> 0 | H37: 0.06 | I37: =+H37*F37 -> 0
A38: 3002104 | B38: ISIS LS bag 2.5kg Lemon | C38: 4 | D38: 723 | F38: =C38*D38*E38 -> 0 | H38: 0.04 | I38: =+H38*F38 -> 0
A39: 3004676 | B39: ISIS gel machine universel 2.5L | C39: 4 | D39: 510 | F39: =C39*D39*E39 -> 0 | H39: 0.04 | I39: =+H39*F39 -> 0
A40: 3004679 | B40: ISIS gel machine universal 900ml | C40: 10 | D40: 265 | F40: =C40*D40*E40 -> 0 | H40: 0.04 | I40: =+H40*F40 -> 0
A41: 3011702 | B41: Bref javel pure power 900mL-DZ | C41: 12 | D41: 86 | F41: =C41*D41*E41 -> 0 | H41: 0.04 | I41: =+H41*F41 -> 0
A42: 3013691 | B42: Bref javel regular pure power 1,75L | C42: 6 | D42: 154 | F42: =C42*D42*E42 -> 0 | H42: 0.04 | I42: =+H42*F42 -> 0
...

Sheet 7
A1: SARL ANDROMEDE DISTRIBUTION
A2: CITE CHAABIA LOT 16 SECTION 02 BIR TOUTA, ALGER.
A3: R-C : 16/00-1010272 B15 I-F : 001516101027219 ART : 16360128161 N° TEL : 0555048930
A5: BON DE LIVRAISON
A7: CLIENT :
A8: ADRESSE :
A9: DATE : | B9: =+'BON DE PREPARATION'!B9 -> 08 07 2023 | D9: LIVREUR :
A11: Code IDH | B11: PRODUITS | C11: Qté/Crt | D11: P.U. | E11: Qté. Vendu | F11: Montant TTC | G11: REMISE SALES BUZZ | H11: % REMISE | I11: REMISE
A12: 2682282 | B12: Le Chat Premium RL 2.5L | C12: 4 | D12: 995 | F12: =C12*D12*E12 -> 0 | H12: 0.06 | I12: =+H12*F12 -> 0
A13: 3035219 | B13: Le Chat LS BAG 2.5kg PROMO | C13: 4 | D13: 695 | F13: =C13*D13*E13 -> 0 | H13: 0.04 | I13: =+H13*F13 -> 0
A14: 3051094 | B14: Bref Moussant 1,75L | C14: 6 | D14: 226 | F14: =C14*D14*E14 -> 0 | H14: 0.04 | I14: =+H14*F14 -> 0
A15: 2823409 | B15: ISIS HS POWDER SDM 300GR LIMITLESS | C15: 25 | D15: 90 | F15: =C15*D15*E15 -> 0 | H15: 0.06 | I15: =+H15*F15 -> 0
A16: 3072722 | B16: BREF Trigger multi-surface 490ml | C16: 12 | D16: 221 | F16: =C16*D16*E16 -> 0 | I16: =+H16*F16 -> 0
A17: 3022693 | B17: Pril ISIS Cold Power 3L Promo | C17: 4 | D17: 595 | F17: =C17*D17*E17 -> 0 | I17: =+H17*F17 -> 0
A18: 2875891 | B18: ISIS HS 300g LEMON LIMITLESS | C18: 25 | D18: 90 | F18: =C18*D18*E18 -> 0 | H18: 0.06 | I18: =+H18*F18 -> 0
A19: 2875892 | B19: ISIS HS 750g LEMON LIMITLESS | C19: 12 | D19: 213 | F19: =C19*D19*E19 -> 0 | H19: 0.06 | I19: =+H19*F19 -> 0
A20: 2875893 | B20: ISIS HS 1,5Kg LEMON LIMITLESS | C20: 8 | D20: 417 | F20: =C20*D20*E20 -> 0 | H20: 0.06 | I20: =+H20*F20 -> 0
A21: 2910278 | B21: Nettoyant Moussant Javelisé 900ml | C21: 12 | D21: 123.5 | F21: =C21*D21*E21 -> 0 | H21: 0.04 | I21: =+H21*F21 -> 0
A22: 2943549 | B22: Pril ISIS Antibactérien 650ML Lemon | C22: 12 | D22: 168 | F22: =C22*D22*E22 -> 0 | I22: =+H22*F22 -> 0
A23: 2951994 | B23: Le Chat Rose 2,5L ADV23 | C23: 4 | D23: 810 | F23: =C23*D23*E23 -> 0 | H23: 0.06 | I23: =+H23*F23 -> 0
A24: 2952074 | B24: Le Chat Regular 2,5L ADV23 | C24: 4 | D24: 810 | F24: =C24*D24*E24 -> 0 | H24: 0.06 | I24: =+H24*F24 -> 0
A25: 2952081 | B25: Le Chat SDM 2,5L ADV23 | C25: 4 | D25: 810 | F25: =C25*D25*E25 -> 0 | H25: 0.06 | I25: =+H25*F25 -> 0
A26: 2952089 | B26: Le Chat Regular 1L ADV23 | C26: 10 | D26: 377 | F26: =C26*D26*E26 -> 0 | H26: 0.06 | I26: =+H26*F26 -> 0
A27: 2952090 | B27: Le Chat Rose 1L ADV23 | C27: 10 | D27: 377 | F27: =C27*D27*E27 -> 0 | H27: 0.06 | I27: =+H27*F27 -> 0
A28: 3035242 | B28: Le chat HDLD 4L ADV 23 non promo | C28: 3 | D28: 1145 | F28: =C28*D28*E28 -> 0 | H28: 0.06 | I28: =+H28*F28 -> 0
A29: 2958928 | B29: Le Chat 2,5kg bag ADV23 | C29: 4 | D29: 792 | F29: =C29*D29*E29 -> 0 | H29: 0.04 | I29: =+H29*F29 -> 0
A30: 2958931 | B30: Le Chat HS Gel 1L ADV23 | C30: 10 | D30: 331 | F30: =C30*D30*E30 -> 0 | H30: 0.04 | I30: =+H30*F30 -> 0
A31: 2958932 | B31: Le Chat HS 300gr ADV23 | C31: 25 | D31: 100 | F31: =C31*D31*E31 -> 0 | H31: 0.04 | I31: =+H31*F31 -> 0
A32: 2958933 | B32: Le Chat HS 750gr ADV23 | C32: 12 | D32: 233 | F32: =C32*D32*E32 -> 0 | H32: 0.04 | I32: =+H32*F32 -> 0
A33: 2970224 | B33: Pril Isis ultra power 1.25L | C33: 12 | D33: 284 | F33: =C33*D33*E33 -> 0 | I33: =+H33*F33 -> 0
A34: 2970482 | B34: Pril Isis ultra power 650ml | C34: 12 | D34: 168 | F34: =C34*D34*E34 -> 0 | I34: =+H34*F34 -> 0
A35: 2975112 | B35: Pril Isis ultra power 3 L | C35: 4 | D35: 664 | F35: =C35*D35*E35 -> 0 | I35: =+H35*F35 -> 0
A36: 2993253 | B36: Bref Triggers Cuisine 500ml | C36: 10 | D36: 221 | F36: =C36*D36*E36 -> 0 | I36: =+H36*F36 -> 0
A37: 2993256 | B37: ISIS Gold 5en1 300g | C37: 25 | D37: 90 | F37: =C37*D37*E37 -> 0 | H37: 0.06 | I37: =+H37*F37 -> 0
A38: 3002104 | B38: ISIS LS bag 2.5kg Lemon | C38: 4 | D38: 723 | F38: =C38*D38*E38 -> 0 | H38: 0.04 | I38: =+H38*F38 -> 0
A39: 3004676 | B39: ISIS gel machine universel 2.5L | C39: 4 | D39: 510 | F39: =C39*D39*E39 -> 0 | H39: 0.04 | I39: =+H39*F39 -> 0
A40: 3004679 | B40: ISIS gel machine universal 900ml | C40: 10 | D40: 265 | F40: =C40*D40*E40 -> 0 | H40: 0.04 | I40: =+H40*F40 -> 0
A41: 3011702 | B41: Bref javel pure power 900mL-DZ | C41: 12 | D41: 86 | F41: =C41*D41*E41 -> 0 | H41: 0.04 | I41: =+H41*F41 -> 0
A42: 3013691 | B42: Bref javel regular pure power 1,75L | C42: 6 | D42: 154 | F42: =C42*D42*E42 -> 0 | H42: 0.04 | I42: =+H42*F42 -> 0
A43: 3013692 | B43: Pril ISIS antibactérien 1.25L | C43: 12 | D43: 284 | F43: =C43*D43*E43 -> 0 | I43: =+H43*F43 -> 0
...

Sheet 8
A1: SARL ANDROMEDE DISTRIBUTION
A2: CITE CHAABIA LOT 16 SECTION 02 BIR TOUTA, ALGER.
A3: R-C : 16/00-1010272 B15 I-F : 001516101027219 ART : 16360128161 N° TEL : 0555048930
A5: BON DE LIVRAISON
A7: CLIENT :
A8: ADRESSE :
A9: DATE : | B9: =+'BON DE PREPARATION'!B9 -> 08 07 2023 | D9: LIVREUR :
A11: Code IDH | B11: PRODUITS | C11: Qté/Crt | D11: P.U. | E11: Qté. Vendu | F11: Montant TTC | G11: REMISE SALES BUZZ | H11: % REMISE | I11: REMISE
A12: 2682282 | B12: Le Chat Premium RL 2.5L | C12: 4 | D12: 995 | F12: =C12*D12*E12 -> 0 | H12: 0.06 | I12: =+H12*F12 -> 0
A13: 3035219 | B13: Le Chat LS BAG 2.5kg PROMO | C13: 4 | D13: 695 | F13: =C13*D13*E13 -> 0 | H13: 0.04 | I13: =+H13*F13 -> 0
A14: 3051094 | B14: Bref Moussant 1,75L | C14: 6 | D14: 226 | F14: =C14*D14*E14 -> 0 | H14: 0.04 | I14: =+H14*F14 -> 0
A15: 2823409 | B15: ISIS HS POWDER SDM 300GR LIMITLESS | C15: 25 | D15: 90 | F15: =C15*D15*E15 -> 0 | H15: 0.06 | I15: =+H15*F15 -> 0
A16: 3072722 | B16: BREF Trigger multi-surface 490ml | C16: 12 | D16: 221 | F16: =C16*D16*E16 -> 0 | I16: =+H16*F16 -> 0
A17: 3022693 | B17: Pril ISIS Cold Power 3L Promo | C17: 4 | D17: 595 | F17: =C17*D17*E17 -> 0 | I17: =+H17*F17 -> 0
A18: 2875891 | B18: ISIS HS 300g LEMON LIMITLESS | C18: 25 | D18: 90 | F18: =C18*D18*E18 -> 0 | H18: 0.06 | I18: =+H18*F18 -> 0
A19: 2875892 | B19: ISIS HS 750g LEMON LIMITLESS | C19: 12 | D19: 213 | F19: =C19*D19*E19 -> 0 | H19: 0.06 | I19: =+H19*F19 -> 0
A20: 2875893 | B20: ISIS HS 1,5Kg LEMON LIMITLESS | C20: 8 | D20: 417 | F20: =C20*D20*E20 -> 0 | H20: 0.06 | I20: =+H20*F20 -> 0
A21: 2910278 | B21: Nettoyant Moussant Javelisé 900ml | C21: 12 | D21: 123.5 | F21: =C21*D21*E21 -> 0 | H21: 0.04 | I21: =+H21*F21 -> 0
A22: 2943549 | B22: Pril ISIS Antibactérien 650ML Lemon | C22: 12 | D22: 168 | F22: =C22*D22*E22 -> 0 | I22: =+H22*F22 -> 0
A23: 2951994 | B23: Le Chat Rose 2,5L ADV23 | C23: 4 | D23: 810 | F23: =C23*D23*E23 -> 0 | H23: 0.06 | I23: =+H23*F23 -> 0
A24: 2952074 | B24: Le Chat Regular 2,5L ADV23 | C24: 4 | D24: 810 | F24: =C24*D24*E24 -> 0 | H24: 0.06 | I24: =+H24*F24 -> 0
A25: 2952081 | B25: Le Chat SDM 2,5L ADV23 | C25: 4 | D25: 810 | F25: =C25*D25*E25 -> 0 | H25: 0.06 | I25: =+H25*F25 -> 0
A26: 2952089 | B26: Le Chat Regular 1L ADV23 | C26: 10 | D26: 377 | F26: =C26*D26*E26 -> 0 | H26: 0.06 | I26: =+H26*F26 -> 0
A27: 2952090 | B27: Le Chat Rose 1L ADV23 | C27: 10 | D27: 377 | F27: =C27*D27*E27 -> 0 | H27: 0.06 | I27: =+H27*F27 -> 0
A28: 3035242 | B28: Le chat HDLD 4L ADV 23 non promo | C28: 3 | D28: 1145 | F28: =C28*D28*E28 -> 0 | H28: 0.06 | I28: =+H28*F28 -> 0
A29: 2958928 | B29: Le Chat 2,5kg bag ADV23 | C29: 4 | D29: 792 | F29: =C29*D29*E29 -> 0 | H29: 0.04 | I29: =+H29*F29 -> 0
A30: 2958931 | B30: Le Chat HS Gel 1L ADV23 | C30: 10 | D30: 331 | F30: =C30*D30*E30 -> 0 | H30: 0.04 | I30: =+H30*F30 -> 0
A31: 2958932 | B31: Le Chat HS 300gr ADV23 | C31: 25 | D31: 100 | F31: =C31*D31*E31 -> 0 | H31: 0.04 | I31: =+H31*F31 -> 0
A32: 2958933 | B32: Le Chat HS 750gr ADV23 | C32: 12 | D32: 233 | F32: =C32*D32*E32 -> 0 | H32: 0.04 | I32: =+H32*F32 -> 0
A33: 2970224 | B33: Pril Isis ultra power 1.25L | C33: 12 | D33: 284 | F33: =C33*D33*E33 -> 0 | I33: =+H33*F33 -> 0
A34: 2970482 | B34: Pril Isis ultra power 650ml | C34: 12 | D34: 168 | F34: =C34*D34*E34 -> 0 | I34: =+H34*F34 -> 0
A35: 2975112 | B35: Pril Isis ultra power 3 L | C35: 4 | D35: 664 | F35: =C35*D35*E35 -> 0 | I35: =+H35*F35 -> 0
A36: 2993253 | B36: Bref Triggers Cuisine 500ml | C36: 10 | D36: 221 | F36: =C36*D36*E36 -> 0 | I36: =+H36*F36 -> 0
A37: 2993256 | B37: ISIS Gold 5en1 300g | C37: 25 | D37: 90 | F37: =C37*D37*E37 -> 0 | H37: 0.06 | I37: =+H37*F37 -> 0
A38: 3002104 | B38: ISIS LS bag 2.5kg Lemon | C38: 4 | D38: 723 | F38: =C38*D38*E38 -> 0 | H38: 0.04 | I38: =+H38*F38 -> 0
A39: 3004676 | B39: ISIS gel machine universel 2.5L | C39: 4 | D39: 510 | F39: =C39*D39*E39 -> 0 | H39: 0.04 | I39: =+H39*F39 -> 0
A40: 3004679 | B40: ISIS gel machine universal 900ml | C40: 10 | D40: 265 | F40: =C40*D40*E40 -> 0 | H40: 0.04 | I40: =+H40*F40 -> 0
A41: 3011702 | B41: Bref javel pure power 900mL-DZ | C41: 12 | D41: 86 | F41: =C41*D41*E41 -> 0 | H41: 0.04 | I41: =+H41*F41 -> 0
A42: 3013691 | B42: Bref javel regular pure power 1,75L | C42: 6 | D42: 154 | F42: =C42*D42*E42 -> 0 | H42: 0.04 | I42: =+H42*F42 -> 0
A43: 3013692 | B43: Pril ISIS antibactérien 1.25L | C43: 12 | D43: 284 | F43: =C43*D43*E43 -> 0 | I43: =+H43*F43 -> 0
...

Sheet 9
A1: SARL ANDROMEDE DISTRIBUTION
A2: CITE CHAABIA LOT 16 SECTION 02 BIR TOUTA, ALGER.
A3: R-C : 16/00-1010272 B15 I-F : 001516101027219 ART : 16360128161 N° TEL : 0555048930
A5: BON DE LIVRAISON
A7: CLIENT :
A8: ADRESSE :
A9: DATE : | B9: =+'BON DE PREPARATION'!B9 -> 08 07 2023 | D9: LIVREUR :
A11: Code IDH | B11: PRODUITS | C11: Qté/Crt | D11: P.U. | E11: Qté. Vendu | F11: Montant TTC | G11: REMISE SALES BUZZ | H11: % REMISE | I11: REMISE
A12: 2682282 | B12: Le Chat Premium RL 2.5L | C12: 4 | D12: 995 | F12: =C12*D12*E12 -> 0 | H12: 0.06 | I12: =+H12*F12 -> 0
A13: 3035219 | B13: Le Chat LS BAG 2.5kg PROMO | C13: 4 | D13: 695 | F13: =C13*D13*E13 -> 0 | H13: 0.04 | I13: =+H13*F13 -> 0
A14: 3051094 | B14: Bref Moussant 1,75L | C14: 6 | D14: 226 | F14: =C14*D14*E14 -> 0 | H14: 0.04 | I14: =+H14*F14 -> 0
A15: 2823409 | B15: ISIS HS POWDER SDM 300GR LIMITLESS | C15: 25 | D15: 90 | F15: =C15*D15*E15 -> 0 | H15: 0.06 | I15: =+H15*F15 -> 0
A16: 3072722 | B16: BREF Trigger multi-surface 490ml | C16: 12 | D16: 221 | F16: =C16*D16*E16 -> 0 | I16: =+H16*F16 -> 0
A17: 3022693 | B17: Pril ISIS Cold Power 3L Promo | C17: 4 | D17: 595 | F17: =C17*D17*E17 -> 0 | I17: =+H17*F17 -> 0
A18: 2875891 | B18: ISIS HS 300g LEMON LIMITLESS | C18: 25 | D18: 90 | F18: =C18*D18*E18 -> 0 | H18: 0.06 | I18: =+H18*F18 -> 0
A19: 2875892 | B19: ISIS HS 750g LEMON LIMITLESS | C19: 12 | D19: 213 | F19: =C19*D19*E19 -> 0 | H19: 0.06 | I19: =+H19*F19 -> 0
A20: 2875893 | B20: ISIS HS 1,5Kg LEMON LIMITLESS | C20: 8 | D20: 417 | F20: =C20*D20*E20 -> 0 | H20: 0.06 | I20: =+H20*F20 -> 0
A21: 2910278 | B21: Nettoyant Moussant Javelisé 900ml | C21: 12 | D21: 123.5 | F21: =C21*D21*E21 -> 0 | H21: 0.04 | I21: =+H21*F21 -> 0
A22: 2943549 | B22: Pril ISIS Antibactérien 650ML Lemon | C22: 12 | D22: 168 | F22: =C22*D22*E22 -> 0 | I22: =+H22*F22 -> 0
A23: 2951994 | B23: Le Chat Rose 2,5L ADV23 | C23: 4 | D23: 810 | F23: =C23*D23*E23 -> 0 | H23: 0.06 | I23: =+H23*F23 -> 0
A24: 2952074 | B24: Le Chat Regular 2,5L ADV23 | C24: 4 | D24: 810 | F24: =C24*D24*E24 -> 0 | H24: 0.06 | I24: =+H24*F24 -> 0
A25: 2952081 | B25: Le Chat SDM 2,5L ADV23 | C25: 4 | D25: 810 | F25: =C25*D25*E25 -> 0 | H25: 0.06 | I25: =+H25*F25 -> 0
A26: 2952089 | B26: Le Chat Regular 1L ADV23 | C26: 10 | D26: 377 | F26: =C26*D26*E26 -> 0 | H26: 0.06 | I26: =+H26*F26 -> 0
A27: 2952090 | B27: Le Chat Rose 1L ADV23 | C27: 10 | D27: 377 | F27: =C27*D27*E27 -> 0 | H27: 0.06 | I27: =+H27*F27 -> 0
A28: 3035242 | B28: Le chat HDLD 4L ADV 23 non promo | C28: 3 | D28: 1145 | F28: =C28*D28*E28 -> 0 | H28: 0.06 | I28: =+H28*F28 -> 0
A29: 2958928 | B29: Le Chat 2,5kg bag ADV23 | C29: 4 | D29: 792 | F29: =C29*D29*E29 -> 0 | H29: 0.04 | I29: =+H29*F29 -> 0
A30: 2958931 | B30: Le Chat HS Gel 1L ADV23 | C30: 10 | D30: 331 | F30: =C30*D30*E30 -> 0 | H30: 0.04 | I30: =+H30*F30 -> 0
A31: 2958932 | B31: Le Chat HS 300gr ADV23 | C31: 25 | D31: 100 | F31: =C31*D31*E31 -> 0 | H31: 0.04 | I31: =+H31*F31 -> 0
A32: 2958933 | B32: Le Chat HS 750gr ADV23 | C32: 12 | D32: 233 | F32: =C32*D32*E32 -> 0 | H32: 0.04 | I32: =+H32*F32 -> 0
A33: 2970224 | B33: Pril Isis ultra power 1.25L | C33: 12 | D33: 284 | F33: =C33*D33*E33 -> 0 | I33: =+H33*F33 -> 0
A34: 2970482 | B34: Pril Isis ultra power 650ml | C34: 12 | D34: 168 | F34: =C34*D34*E34 -> 0 | I34: =+H34*F34 -> 0
A35: 2975112 | B35: Pril Isis ultra power 3 L | C35: 4 | D35: 664 | F35: =C35*D35*E35 -> 0 | I35: =+H35*F35 -> 0
A36: 2993253 | B36: Bref Triggers Cuisine 500ml | C36: 10 | D36: 221 | F36: =C36*D36*E36 -> 0 | I36: =+H36*F36 -> 0
A37: 2993256 | B37: ISIS Gold 5en1 300g | C37: 25 | D37: 90 | F37: =C37*D37*E37 -> 0 | H37: 0.06 | I37: =+H37*F37 -> 0
A38: 3002104 | B38: ISIS LS bag 2.5kg Lemon | C38: 4 | D38: 723 | F38: =C38*D38*E38 -> 0 | H38: 0.04 | I38: =+H38*F38 -> 0
A39: 3004676 | B39: ISIS gel machine universel 2.5L | C39: 4 | D39: 510 | F39: =C39*D39*E39 -> 0 | H39: 0.04 | I39: =+H39*F39 -> 0
A40: 3004679 | B40: ISIS gel machine universal 900ml | C40: 10 | D40: 265 | F40: =C40*D40*E40 -> 0 | H40: 0.04 | I40: =+H40*F40 -> 0
A41: 3011702 | B41: Bref javel pure power 900mL-DZ | C41: 12 | D41: 86 | F41: =C41*D41*E41 -> 0 | H41: 0.04 | I41: =+H41*F41 -> 0
A42: 3013691 | B42: Bref javel regular pure power 1,75L | C42: 6 | D42: 154 | F42: =C42*D42*E42 -> 0 | H42: 0.04 | I42: =+H42*F42 -> 0
A43: 3013692 | B43: Pril ISIS antibactérien 1.25L | C43: 12 | D43: 284 | F43: =C43*D43*E43 -> 0 | I43: =+H43*F43 -> 0
...

Sheet 10
A1: SARL ANDROMEDE DISTRIBUTION
A2: CITE CHAABIA LOT 16 SECTION 02 BIR TOUTA, ALGER.
A3: R-C : 16/00-1010272 B15 I-F : 001516101027219 ART : 16360128161 N° TEL : 0555048930
A5: BON DE LIVRAISON
A7: CLIENT :
A8: ADRESSE :
A9: DATE : | B9: =+'BON DE PREPARATION'!B9 -> 08 07 2023 | D9: LIVREUR :
A11: Code IDH | B11: PRODUITS | C11: Qté/Crt | D11: P.U. | E11: Qté. Vendu | F11: Montant TTC | G11: REMISE SALES BUZZ | H11: % REMISE | I11: REMISE
A12: 2682282 | B12: Le Chat Premium RL 2.5L | C12: 4 | D12: 995 | F12: =C12*D12*E12 -> 0 | H12: 0.06 | I12: =+H12*F12 -> 0
A13: 3035219 | B13: Le Chat LS BAG 2.5kg PROMO | C13: 4 | D13: 695 | F13: =C13*D13*E13 -> 0 | H13: 0.04 | I13: =+H13*F13 -> 0
A14: 3051094 | B14: Bref Moussant 1,75L | C14: 6 | D14: 226 | F14: =C14*D14*E14 -> 0 | H14: 0.04 | I14: =+H14*F14 -> 0
A15: 2823409 | B15: ISIS HS POWDER SDM 300GR LIMITLESS | C15: 25 | D15: 90 | F15: =C15*D15*E15 -> 0 | H15: 0.06 | I15: =+H15*F15 -> 0
A16: 3072722 | B16: BREF Trigger multi-surface 490ml | C16: 12 | D16: 221 | F16: =C16*D16*E16 -> 0 | I16: =+H16*F16 -> 0
A17: 3022693 | B17: Pril ISIS Cold Power 3L Promo | C17: 4 | D17: 595 | F17: =C17*D17*E17 -> 0 | I17: =+H17*F17 -> 0
A18: 2875891 | B18: ISIS HS 300g LEMON LIMITLESS | C18: 25 | D18: 90 | F18: =C18*D18*E18 -> 0 | H18: 0.06 | I18: =+H18*F18 -> 0
A19: 2875892 | B19: ISIS HS 750g LEMON LIMITLESS | C19: 12 | D19: 213 | F19: =C19*D19*E19 -> 0 | H19: 0.06 | I19: =+H19*F19 -> 0
A20: 2875893 | B20: ISIS HS 1,5Kg LEMON LIMITLESS | C20: 8 | D20: 417 | F20: =C20*D20*E20 -> 0 | H20: 0.06 | I20: =+H20*F20 -> 0
A21: 2910278 | B21: Nettoyant Moussant Javelisé 900ml | C21: 12 | D21: 123.5 | F21: =C21*D21*E21 -> 0 | H21: 0.04 | I21: =+H21*F21 -> 0
A22: 2943549 | B22: Pril ISIS Antibactérien 650ML Lemon | C22: 12 | D22: 168 | F22: =C22*D22*E22 -> 0 | I22: =+H22*F22 -> 0
A23: 2951994 | B23: Le Chat Rose 2,5L ADV23 | C23: 4 | D23: 810 | F23: =C23*D23*E23 -> 0 | H23: 0.06 | I23: =+H23*F23 -> 0
A24: 2952074 | B24: Le Chat Regular 2,5L ADV23 | C24: 4 | D24: 810 | F24: =C24*D24*E24 -> 0 | H24: 0.06 | I24: =+H24*F24 -> 0
A25: 2952081 | B25: Le Chat SDM 2,5L ADV23 | C25: 4 | D25: 810 | F25: =C25*D25*E25 -> 0 | H25: 0.06 | I25: =+H25*F25 -> 0
A26: 2952089 | B26: Le Chat Regular 1L ADV23 | C26: 10 | D26: 377 | F26: =C26*D26*E26 -> 0 | H26: 0.06 | I26: =+H26*F26 -> 0
A27: 2952090 | B27: Le Chat Rose 1L ADV23 | C27: 10 | D27: 377 | F27: =C27*D27*E27 -> 0 | H27: 0.06 | I27: =+H27*F27 -> 0
A28: 3035242 | B28: Le chat HDLD 4L ADV 23 non promo | C28: 3 | D28: 1145 | F28: =C28*D28*E28 -> 0 | H28: 0.06 | I28: =+H28*F28 -> 0
A29: 2958928 | B29: Le Chat 2,5kg bag ADV23 | C29: 4 | D29: 792 | F29: =C29*D29*E29 -> 0 | H29: 0.04 | I29: =+H29*F29 -> 0
A30: 2958931 | B30: Le Chat HS Gel 1L ADV23 | C30: 10 | D30: 331 | F30: =C30*D30*E30 -> 0 | H30: 0.04 | I30: =+H30*F30 -> 0
A31: 2958932 | B31: Le Chat HS 300gr ADV23 | C31: 25 | D31: 100 | F31: =C31*D31*E31 -> 0 | H31: 0.04 | I31: =+H31*F31 -> 0
A32: 2958933 | B32: Le Chat HS 750gr ADV23 | C32: 12 | D32: 233 | F32: =C32*D32*E32 -> 0 | H32: 0.04 | I32: =+H32*F32 -> 0
A33: 2970224 | B33: Pril Isis ultra power 1.25L | C33: 12 | D33: 284 | F33: =C33*D33*E33 -> 0 | I33: =+H33*F33 -> 0
A34: 2970482 | B34: Pril Isis ultra power 650ml | C34: 12 | D34: 168 | F34: =C34*D34*E34 -> 0 | I34: =+H34*F34 -> 0
A35: 2975112 | B35: Pril Isis ultra power 3 L | C35: 4 | D35: 664 | F35: =C35*D35*E35 -> 0 | I35: =+H35*F35 -> 0
A36: 2993253 | B36: Bref Triggers Cuisine 500ml | C36: 10 | D36: 221 | F36: =C36*D36*E36 -> 0 | I36: =+H36*F36 -> 0
A37: 2993256 | B37: ISIS Gold 5en1 300g | C37: 25 | D37: 90 | F37: =C37*D37*E37 -> 0 | H37: 0.06 | I37: =+H37*F37 -> 0
A38: 3002104 | B38: ISIS LS bag 2.5kg Lemon | C38: 4 | D38: 723 | F38: =C38*D38*E38 -> 0 | H38: 0.04 | I38: =+H38*F38 -> 0
A39: 3004676 | B39: ISIS gel machine universel 2.5L | C39: 4 | D39: 510 | F39: =C39*D39*E39 -> 0 | H39: 0.04 | I39: =+H39*F39 -> 0
A40: 3004679 | B40: ISIS gel machine universal 900ml | C40: 10 | D40: 265 | F40: =C40*D40*E40 -> 0 | H40: 0.04 | I40: =+H40*F40 -> 0
A41: 3011702 | B41: Bref javel pure power 900mL-DZ | C41: 12 | D41: 86 | F41: =C41*D41*E41 -> 0 | H41: 0.04 | I41: =+H41*F41 -> 0
A42: 3013691 | B42: Bref javel regular pure power 1,75L | C42: 6 | D42: 154 | F42: =C42*D42*E42 -> 0 | H42: 0.04 | I42: =+H42*F42 -> 0
A43: 3013692 | B43: Pril ISIS antibactérien 1.25L | C43: 12 | D43: 284 | F43: =C43*D43*E43 -> 0 | I43: =+H43*F43 -> 0
...

Sheet 11
A1: SARL ANDROMEDE DISTRIBUTION
A2: CITE CHAABIA LOT 16 SECTION 02 BIR TOUTA, ALGER.
A3: R-C : 16/00-1010272 B15 I-F : 001516101027219 ART : 16360128161 N° TEL : 0555048930
A5: BON DE LIVRAISON
A7: CLIENT :
A8: ADRESSE :
A9: DATE : | B9: =+'BON DE PREPARATION'!B9 -> 08 07 2023 | D9: LIVREUR :
A11: Code IDH | B11: PRODUITS | C11: Qté/Crt | D11: P.U. | E11: Qté. Vendu | F11: Montant TTC | G11: REMISE SALES BUZZ | H11: % REMISE | I11: REMISE
A12: 2682282 | B12: Le Chat Premium RL 2.5L | C12: 4 | D12: 995 | F12: =C12*D12*E12 -> 0 | H12: 0.06 | I12: =+H12*F12 -> 0
A13: 3035219 | B13: Le Chat LS BAG 2.5kg PROMO | C13: 4 | D13: 695 | F13: =C13*D13*E13 -> 0 | H13: 0.04 | I13: =+H13*F13 -> 0
A14: 3051094 | B14: Bref Moussant 1,75L | C14: 6 | D14: 226 | F14: =C14*D14*E14 -> 0 | H14: 0.04 | I14: =+H14*F14 -> 0
A15: 2823409 | B15: ISIS HS POWDER SDM 300GR LIMITLESS | C15: 25 | D15: 90 | F15: =C15*D15*E15 -> 0 | H15: 0.06 | I15: =+H15*F15 -> 0
A16: 3072722 | B16: BREF Trigger multi-surface 490ml | C16: 12 | D16: 221 | F16: =C16*D16*E16 -> 0 | I16: =+H16*F16 -> 0
A17: 3022693 | B17: Pril ISIS Cold Power 3L Promo | C17: 4 | D17: 595 | F17: =C17*D17*E17 -> 0 | I17: =+H17*F17 -> 0
A18: 2875891 | B18: ISIS HS 300g LEMON LIMITLESS | C18: 25 | D18: 90 | F18: =C18*D18*E18 -> 0 | H18: 0.06 | I18: =+H18*F18 -> 0
A19: 2875892 | B19: ISIS HS 750g LEMON LIMITLESS | C19: 12 | D19: 213 | F19: =C19*D19*E19 -> 0 | H19: 0.06 | I19: =+H19*F19 -> 0
A20: 2875893 | B20: ISIS HS 1,5Kg LEMON LIMITLESS | C20: 8 | D20: 417 | F20: =C20*D20*E20 -> 0 | H20: 0.06 | I20: =+H20*F20 -> 0
A21: 2910278 | B21: Nettoyant Moussant Javelisé 900ml | C21: 12 | D21: 123.5 | F21: =C21*D21*E21 -> 0 | H21: 0.04 | I21: =+H21*F21 -> 0
A22: 2943549 | B22: Pril ISIS Antibactérien 650ML Lemon | C22: 12 | D22: 168 | F22: =C22*D22*E22 -> 0 | I22: =+H22*F22 -> 0
A23: 2951994 | B23: Le Chat Rose 2,5L ADV23 | C23: 4 | D23: 810 | F23: =C23*D23*E23 -> 0 | H23: 0.06 | I23: =+H23*F23 -> 0
A24: 2952074 | B24: Le Chat Regular 2,5L ADV23 | C24: 4 | D24: 810 | F24: =C24*D24*E24 -> 0 | H24: 0.06 | I24: =+H24*F24 -> 0
A25: 2952081 | B25: Le Chat SDM 2,5L ADV23 | C25: 4 | D25: 810 | F25: =C25*D25*E25 -> 0 | H25: 0.06 | I25: =+H25*F25 -> 0
A26: 2952089 | B26: Le Chat Regular 1L ADV23 | C26: 10 | D26: 377 | F26: =C26*D26*E26 -> 0 | H26: 0.06 | I26: =+H26*F26 -> 0
A27: 2952090 | B27: Le Chat Rose 1L ADV23 | C27: 10 | D27: 377 | F27: =C27*D27*E27 -> 0 | H27: 0.06 | I27: =+H27*F27 -> 0
A28: 3035242 | B28: Le chat HDLD 4L ADV 23 non promo | C28: 3 | D28: 1145 | F28: =C28*D28*E28 -> 0 | H28: 0.06 | I28: =+H28*F28 -> 0
A29: 2958928 | B29: Le Chat 2,5kg bag ADV23 | C29: 4 | D29: 792 | F29: =C29*D29*E29 -> 0 | H29: 0.04 | I29: =+H29*F29 -> 0
A30: 2958931 | B30: Le Chat HS Gel 1L ADV23 | C30: 10 | D30: 331 | F30: =C30*D30*E30 -> 0 | H30: 0.04 | I30: =+H30*F30 -> 0
A31: 2958932 | B31: Le Chat HS 300gr ADV23 | C31: 25 | D31: 100 | F31: =C31*D31*E31 -> 0 | H31: 0.04 | I31: =+H31*F31 -> 0
A32: 2958933 | B32: Le Chat HS 750gr ADV23 | C32: 12 | D32: 233 | F32: =C32*D32*E32 -> 0 | H32: 0.04 | I32: =+H32*F32 -> 0
A33: 2970224 | B33: Pril Isis ultra power 1.25L | C33: 12 | D33: 284 | F33: =C33*D33*E33 -> 0 | I33: =+H33*F33 -> 0
A34: 2970482 | B34: Pril Isis ultra power 650ml | C34: 12 | D34: 168 | F34: =C34*D34*E34 -> 0 | I34: =+H34*F34 -> 0
A35: 2975112 | B35: Pril Isis ultra power 3 L | C35: 4 | D35: 664 | F35: =C35*D35*E35 -> 0 | I35: =+H35*F35 -> 0
A36: 2993253 | B36: Bref Triggers Cuisine 500ml | C36: 10 | D36: 221 | F36: =C36*D36*E36 -> 0 | I36: =+H36*F36 -> 0
A37: 2993256 | B37: ISIS Gold 5en1 300g | C37: 25 | D37: 90 | F37: =C37*D37*E37 -> 0 | H37: 0.06 | I37: =+H37*F37 -> 0
A38: 3002104 | B38: ISIS LS bag 2.5kg Lemon | C38: 4 | D38: 723 | F38: =C38*D38*E38 -> 0 | H38: 0.04 | I38: =+H38*F38 -> 0
A39: 3004676 | B39: ISIS gel machine universel 2.5L | C39: 4 | D39: 510 | F39: =C39*D39*E39 -> 0 | H39: 0.04 | I39: =+H39*F39 -> 0
A40: 3004679 | B40: ISIS gel machine universal 900ml | C40: 10 | D40: 265 | F40: =C40*D40*E40 -> 0 | H40: 0.04 | I40: =+H40*F40 -> 0
A41: 3011702 | B41: Bref javel pure power 900mL-DZ | C41: 12 | D41: 86 | F41: =C41*D41*E41 -> 0 | H41: 0.04 | I41: =+H41*F41 -> 0
A42: 3013691 | B42: Bref javel regular pure power 1,75L | C42: 6 | D42: 154 | F42: =C42*D42*E42 -> 0 | H42: 0.04 | I42: =+H42*F42 -> 0
A43: 3013692 | B43: Pril ISIS antibactérien 1.25L | C43: 12 | D43: 284 | F43: =C43*D43*E43 -> 0 | I43: =+H43*F43 -> 0
...

Sheet 12
A1: SARL ANDROMEDE DISTRIBUTION
A2: CITE CHAABIA LOT 16 SECTION 02 BIR TOUTA, ALGER.
A3: R-C : 16/00-1010272 B15 I-F : 001516101027219 ART : 16360128161 N° TEL : 0555048930
A5: BON DE LIVRAISON
A7: CLIENT :
A8: ADRESSE :
A9: DATE : | B9: =+'BON DE PREPARATION'!B9 -> 08 07 2023 | D9: LIVREUR :
A11: Code IDH | B11: PRODUITS | C11: Qté/Crt | D11: P.U. | E11: Qté. Vendu | F11: Montant TTC | G11: REMISE SALES BUZZ | H11: % REMISE | I11: REMISE
A12: 2682282 | B12: Le Chat Premium RL 2.5L | C12: 4 | D12: 995 | F12: =C12*D12*E12 -> 0 | H12: 0.06 | I12: =+H12*F12 -> 0
A13: 3035219 | B13: Le Chat LS BAG 2.5kg PROMO | C13: 4 | D13: 695 | F13: =C13*D13*E13 -> 0 | H13: 0.04 | I13: =+H13*F13 -> 0
A14: 3051094 | B14: Bref Moussant 1,75L | C14: 6 | D14: 226 | F14: =C14*D14*E14 -> 0 | H14: 0.04 | I14: =+H14*F14 -> 0
A15: 2823409 | B15: ISIS HS POWDER SDM 300GR LIMITLESS | C15: 25 | D15: 90 | F15: =C15*D15*E15 -> 0 | H15: 0.06 | I15: =+H15*F15 -> 0
A16: 3072722 | B16: BREF Trigger multi-surface 490ml | C16: 12 | D16: 221 | F16: =C16*D16*E16 -> 0 | I16: =+H16*F16 -> 0
